Workbook

Sheet Start here
A1: CBS Talks Partnerships
A2: Spreadsheet MVP of docs/lean-spec.md. Two scores only: Fit (0–10) and Access (0–4). No budget estimates.
A4: How to use it
A5: 1. Delete the example rows: every row whose company or name ends in '(example)', in all tabs.
A6: 2. Fill in the 'CBS Talks' tab: semester dates and target, then Team, Packages, Themes and Events.
A7: 3. Import past and current partners: Companies + Opportunities (Won, with renewal date and satisfaction) + Commercial Evidence.
A8: 4. Rate companies in 'Companies' (F1, F2, F3, F5 with a reason; a source for every 2) and add at least one Commercial Evidence row.
A9: 5. Every week (30 min): open 'Work Queue', work it top to bottom, log contacts in 'Interactions', update stages and next actions.
A11: Colours
A12: Yellow cells: type here. Grey cells: calculated, don't edit. Dark-blue headers: input columns. Grey headers: calculated columns.
A13: Hover a header in 'Companies' to see the rating anchors.
A15: The rules in one place
... A28: All example companies, people and amounts are fictional.

Sheet Work Queue
A1: Work Queue
A2: ="As of "&TEXT(S_Today,"d mmm yyyy")&" · Work from the top: renewals → follow-ups → Priority prospects → building paths. Calculated, don't edit: update the Opportunities and Companies tabs instead." -> As of 12 Oct 2026 · Work from the top: renewals → follow-ups → Priority prospects → building paths. Calculated, don't edit: update the Opportunities and Companies tabs instead.
A4: 1–2 · Renewals and follow-ups (from Opportunities)
A5: # | B5: Why it's here | C5: Company | D5: Type | E5: Stage | F5: Owner | G5: Next action | H5: Due | I5: Renewal date | J5: key
A6: =IF($J6="","",1) -> 1 | B6: =IF($J6="","",INDEX(Opportunities!$Y$3:$Y$502,MATCH($J6,Opportunities!$Z$3:$Z$502,0))) -> Renewal due | C6: =IF($J6="","",INDEX(Opportunities!$A$3:$A$502,MATCH($J6,Opportunities!$Z$3:$Z$502,0))) -> ProServ (example) | D6: =IF($J6="","",INDEX(Opportunities!$B$3:$B$502,MATCH($J6,Opportunities!$Z$3:$Z$502,0))) -> Recurring sponsor | E6: =IF($J6="","",INDEX(Opportunities!$C$3:$C$502,MATCH($J6,Opportunities!$Z$3:$Z$502,0))) -> Won | F6: =IF($J6="","",IF(INDEX(Opportunities!$D$3:$D$502,MATCH($J6,Opportunities!$Z$3:$Z$502,0))="","(no owner)",INDEX(Opportunities!$D$3:$D$502,MATCH($J6,Opportunities!$Z$3:$Z$502,0)))) -> J.H. (example) | G6: =IF($J6="","",IF(INDEX(Opportunities!$L$3:$L$502,MATCH($J6,Opportunities!$Z$3:$Z$502,0))="","(add a next action)",INDEX(Opportunities!$L$3:$L$502,MATCH($J6,Opportunities!$Z$3:$Z$502,0)))) -> (add a next action) | H6: =IF($J6="","",IF(INDEX(Opportunities!$M$3:$M$502,MATCH($J6,Opportunities!$Z$3:$Z$502,0))="","",INDEX(Opportunities!$M$3:$M$502,MATCH($J6,Opportunities!$Z$3:$Z$502,0)))) | I6: =IF($J6="","",IF(INDEX(Opportunities!$P$3:$P$502,MATCH($J6,Opportunities!$Z$3:$Z$502,0))="","",INDEX(Opportunities!$P$3:$P$502,MATCH($J6,Opportunities!$Z$3:$Z$502,0)))) -> 46337 | J6: =IFERROR(SMALL(Opportunities!$Z$3:$Z$502,1),"") -> 106337
A7: =IF($J7="","",2) -> 2 | B7: =IF($J7="","",INDEX(Opportunities!$Y$3:$Y$502,MATCH($J7,Opportunities!$Z$3:$Z$502,0))) -> Overdue | C7: =IF($J7="","",INDEX(Opportunities!$A$3:$A$502,MATCH($J7,Opportunities!$Z$3:$Z$502,0))) -> MegaBrand A/S (example) | D7: =IF($J7="","",INDEX(Opportunities!$B$3:$B$502,MATCH($J7,Opportunities!$Z$3:$Z$502,0))) -> Recruitment | E7: =IF($J7="","",INDEX(Opportunities!$C$3:$C$502,MATCH($J7,Opportunities!$Z$3:$Z$502,0))) -> Contacted | F7: =IF($J7="","",IF(INDEX(Opportunities!$D$3:$D$502,MATCH($J7,Opportunities!$Z$3:$Z$502,0))="","(no owner)",INDEX(Opportunities!$D$3:$D$502,MATCH($J7,Opportunities!$Z$3:$Z$502,0)))) -> M.S. (example) | G7: =IF($J7="","",IF(INDEX(Opportunities!$L$3:$L$502,MATCH($J7,Opportunities!$Z$3:$Z$502,0))="","(add a next action)",INDEX(Opportunities!$L$3:$L$502,MATCH($J7,Opportunities!$Z$3:$Z$502,0)))) -> Second follow-up email | H7: =IF($J7="","",IF(INDEX(Opportunities!$M$3:$M$502,MATCH($J7,Opportunities!$Z$3:$Z$502,0))="","",INDEX(Opportunities!$M$3:$M$502,MATCH($J7,Opportunities!$Z$3:$Z$502,0)))) -> 46304 | I7: =IF($J7="","",IF(INDEX(Opportunities!$P$3:$P$502,MATCH($J7,Opportunities!$Z$3:$Z$502,0))="","",INDEX(Opportunities!$P$3:$P$502,MATCH($J7,Opportunities!$Z$3:$Z$502,0)))) | J7: =IFERROR(SMALL(Opportunities!$Z$3:$Z$502,2),"") -> 206304
A8: =IF($J8="","",3) -> 3 | B8: =IF($J8="","",INDEX(Opportunities!$Y$3:$Y$502,MATCH($J8,Opportunities!$Z$3:$Z$502,0))) -> Due this week | C8: =IF($J8="","",INDEX(Opportunities!$A$3:$A$502,MATCH($J8,Opportunities!$Z$3:$Z$502,0))) -> Fjord Ventures (example) | D8: =IF($J8="","",INDEX(Opportunities!$B$3:$B$502,MATCH($J8,Opportunities!$Z$3:$Z$502,0))) -> Speaker | E8: =IF($J8="","",INDEX(Opportunities!$C$3:$C$502,MATCH($J8,Opportunities!$Z$3:$Z$502,0))) -> Meeting | F8: =IF($J8="","",IF(INDEX(Opportunities!$D$3:$D$502,MATCH($J8,Opportunities!$Z$3:$Z$502,0))="","(no owner)",INDEX(Opportunities!$D$3:$D$502,MATCH($J8,Opportunities!$Z$3:$Z$502,0)))) -> A.K. (example) | G8: =IF($J8="","",IF(INDEX(Opportunities!$L$3:$L$502,MATCH($J8,Opportunities!$Z$3:$Z$502,0))="","(add a next action)",INDEX(Opportunities!$L$3:$L$502,MATCH($J8,Opportunities!$Z$3:$Z$502,0)))) -> Meeting: confirm keynote date | H8: =IF($J8="","",IF(INDEX(Opportunities!$M$3:$M$502,MATCH($J8,Opportunities!$Z$3:$Z$502,0))="","",INDEX(Opportunities!$M$3:$M$502,MATCH($J8,Opportunities!$Z$3:$Z$502,0)))) -> 46311 | I8: =IF($J8="","",IF(INDEX(Opportunities!$P$3:$P$502,MATCH($J8,Opportunities!$Z$3:$Z$502,0))="","",INDEX(Opportunities!$P$3:$P$502,MATCH($J8,Opportunities!$Z$3:$Z$502,0)))) | J8: =IFERROR(SMALL(Opportunities!$Z$3:$Z$502,3),"") -> 406311
A9: =IF($J9="","",4) -> 4 | B9: =IF($J9="","",INDEX(Opportunities!$Y$3:$Y$502,MATCH($J9,Opportunities!$Z$3:$Z$502,0))) -> Due this week | C9: =IF($J9="","",INDEX(Opportunities!$A$3:$A$502,MATCH($J9,Opportunities!$Z$3:$Z$502,0))) -> Kobber Hotels (example) | D9: =IF($J9="","",INDEX(Opportunities!$B$3:$B$502,MATCH($J9,Opportunities!$Z$3:$Z$502,0))) -> In-kind | E9: =IF($J9="","",INDEX(Opportunities!$C$3:$C$502,MATCH($J9,Opportunities!$Z$3:$Z$502,0))) -> Proposal sent | F9: =IF($J9="","",IF(INDEX(Opportunities!$D$3:$D$502,MATCH($J9,Opportunities!$Z$3:$Z$502,0))="","(no owner)",INDEX(Opportunities!$D$3:$D$502,MATCH($J9,Opportunities!$Z$3:$Z$502,0)))) -> L.M. (example) | G9: =IF($J9="","",IF(INDEX(Opportunities!$L$3:$L$502,MATCH($J9,Opportunities!$Z$3:$Z$502,0))="","(add a next action)",INDEX(Opportunities!$L$3:$L$502,MATCH($J9,Opportunities!$Z$3:$Z$502,0)))) -> Check venue availability | H9: =IF($J9="","",IF(INDEX(Opportunities!$M$3:$M$502,MATCH($J9,Opportunities!$Z$3:$Z$502,0))="","",INDEX(Opportunities!$M$3:$M$502,MATCH($J9,Opportunities!$Z$3:$Z$502,0)))) -> 46313 | I9: =IF($J9="","",IF(INDEX(Opportunities!$P$3:$P$502,MATCH($J9,Opportunities!$Z$3:$Z$502,0))="","",INDEX(Opportunities!$P$3:$P$502,MATCH($J9,Opportunities!$Z$3:$Z$502,0)))) | J9: =IFERROR(SMALL(Opportunities!$Z$3:$Z$502,4),"") -> 406313
A10: =IF($J10="","",5) | B10: =IF($J10="","",INDEX(Opportunities!$Y$3:$Y$502,MATCH($J10,Opportunities!$Z$3:$Z$502,0))) | C10: =IF($J10="","",INDEX(Opportunities!$A$3:$A$502,MATCH($J10,Opportunities!$Z$3:$Z$502,0))) | D10: =IF($J10="","",INDEX(Opportunities!$B$3:$B$502,MATCH($J10,Opportunities!$Z$3:$Z$502,0))) | E10: =IF($J10="","",INDEX(Opportunities!$C$3:$C$502,MATCH($J10,Opportunities!$Z$3:$Z$502,0))) | F10: =IF($J10="","",IF(INDEX(Opportunities!$D$3:$D$502,MATCH($J10,Opportunities!$Z$3:$Z$502,0))="","(no owner)",INDEX(Opportunities!$D$3:$D$502,MATCH($J10,Opportunities!$Z$3:$Z$502,0)))) | G10: =IF($J10="","",IF(INDEX(Opportunities!$L$3:$L$502,MATCH($J10,Opportunities!$Z$3:$Z$502,0))="","(add a next action)",INDEX(Opportunities!$L$3:$L$502,MATCH($J10,Opportunities!$Z$3:$Z$502,0)))) | H10: =IF($J10="","",IF(INDEX(Opportunities!$M$3:$M$502,MATCH($J10,Opportunities!$Z$3:$Z$502,0))="","",INDEX(Opportunities!$M$3:$M$502,MATCH($J10,Opportunities!$Z$3:$Z$502,0)))) | I10: =IF($J10="","",IF(INDEX(Opportunities!$P$3:$P$502,MATCH($J10,Opportunities!$Z$3:$Z$502,0))="","",INDEX(Opportunities!$P$3:$P$502,MATCH($J10,Opportunities!$Z$3:$Z$502,0)))) | J10: =IFERROR(SMALL(Opportunities!$Z$3:$Z$502,5),"")
A11: =IF($J11="","",6) | B11: =IF($J11="","",INDEX(Opportunities!$Y$3:$Y$502,MATCH($J11,Opportunities!$Z$3:$Z$502,0))) | C11: =IF($J11="","",INDEX(Opportunities!$A$3:$A$502,MATCH($J11,Opportunities!$Z$3:$Z$502,0))) | D11: =IF($J11="","",INDEX(Opportunities!$B$3:$B$502,MATCH($J11,Opportunities!$Z$3:$Z$502,0))) | E11: =IF($J11="","",INDEX(Opportunities!$C$3:$C$502,MATCH($J11,Opportunities!$Z$3:$Z$502,0))) | F11: =IF($J11="","",IF(INDEX(Opportunities!$D$3:$D$502,MATCH($J11,Opportunities!$Z$3:$Z$502,0))="","(no owner)",INDEX(Opportunities!$D$3:$D$502,MATCH($J11,Opportunities!$Z$3:$Z$502,0)))) | G11: =IF($J11="","",IF(INDEX(Opportunities!$L$3:$L$502,MATCH($J11,Opportunities!$Z$3:$Z$502,0))="","(add a next action)",INDEX(Opportunities!$L$3:$L$502,MATCH($J11,Opportunities!$Z$3:$Z$502,0)))) | H11: =IF($J11="","",IF(INDEX(Opportunities!$M$3:$M$502,MATCH($J11,Opportunities!$Z$3:$Z$502,0))="","",INDEX(Opportunities!$M$3:$M$502,MATCH($J11,Opportunities!$Z$3:$Z$502,0)))) | I11: =IF($J11="","",IF(INDEX(Opportunities!$P$3:$P$502,MATCH($J11,Opportunities!$Z$3:$Z$502,0))="","",INDEX(Opportunities!$P$3:$P$502,MATCH($J11,Opportunities!$Z$3:$Z$502,0)))) | J11: =IFERROR(SMALL(Opportunities!$Z$3:$Z$502,6),"")
A12: =IF($J12="","",7) | B12: =IF($J12="","",INDEX(Opportunities!$Y$3:$Y$502,MATCH($J12,Opportunities!$Z$3:$Z$502,0))) | C12: =IF($J12="","",INDEX(Opportunities!$A$3:$A$502,MATCH($J12,Opportunities!$Z$3:$Z$502,0))) | D12: =IF($J12="","",INDEX(Opportunities!$B$3:$B$502,MATCH($J12,Opportunities!$Z$3:$Z$502,0))) | E12: =IF($J12="","",INDEX(Opportunities!$C$3:$C$502,MATCH($J12,Opportunities!$Z$3:$Z$502,0))) | F12: =IF($J12="","",IF(INDEX(Opportunities!$D$3:$D$502,MATCH($J12,Opportunities!$Z$3:$Z$502,0))="","(no owner)",INDEX(Opportunities!$D$3:$D$502,MATCH($J12,Opportunities!$Z$3:$Z$502,0)))) | G12: =IF($J12="","",IF(INDEX(Opportunities!$L$3:$L$502,MATCH($J12,Opportunities!$Z$3:$Z$502,0))="","(add a next action)",INDEX(Opportunities!$L$3:$L$502,MATCH($J12,Opportunities!$Z$3:$Z$502,0)))) | H12: =IF($J12="","",IF(INDEX(Opportunities!$M$3:$M$502,MATCH($J12,Opportunities!$Z$3:$Z$502,0))="","",INDEX(Opportunities!$M$3:$M$502,MATCH($J12,Opportunities!$Z$3:$Z$502,0)))) | I12: =IF($J12="","",IF(INDEX(Opportunities!$P$3:$P$502,MATCH($J12,Opportunities!$Z$3:$Z$502,0))="","",INDEX(Opportunities!$P$3:$P$502,MATCH($J12,Opportunities!$Z$3:$Z$502,0)))) | J12: =IFERROR(SMALL(Opportunities!$Z$3:$Z$502,7),"")
A13: =IF($J13="","",8) | B13: =IF($J13="","",INDEX(Opportunities!$Y$3:$Y$502,MATCH($J13,Opportunities!$Z$3:$Z$502,0))) | C13: =IF($J13="","",INDEX(Opportunities!$A$3:$A$502,MATCH($J13,Opportunities!$Z$3:$Z$502,0))) | D13: =IF($J13="","",INDEX(Opportunities!$B$3:$B$502,MATCH($J13,Opportunities!$Z$3:$Z$502,0))) | E13: =IF($J13="","",INDEX(Opportunities!$C$3:$C$502,MATCH($J13,Opportunities!$Z$3:$Z$502,0))) | F13: =IF($J13="","",IF(INDEX(Opportunities!$D$3:$D$502,MATCH($J13,Opportunities!$Z$3:$Z$502,0))="","(no owner)",INDEX(Opportunities!$D$3:$D$502,MATCH($J13,Opportunities!$Z$3:$Z$502,0)))) | G13: =IF($J13="","",IF(INDEX(Opportunities!$L$3:$L$502,MATCH($J13,Opportunities!$Z$3:$Z$502,0))="","(add a next action)",INDEX(Opportunities!$L$3:$L$502,MATCH($J13,Opportunities!$Z$3:$Z$502,0)))) | H13: =IF($J13="","",IF(INDEX(Opportunities!$M$3:$M$502,MATCH($J13,Opportunities!$Z$3:$Z$502,0))="","",INDEX(Opportunities!$M$3:$M$502,MATCH($J13,Opportunities!$Z$3:$Z$502,0)))) | I13: =IF($J13="","",IF(INDEX(Opportunities!$P$3:$P$502,MATCH($J13,Opportunities!$Z$3:$Z$502,0))="","",INDEX(Opportunities!$P$3:$P$502,MATCH($J13,Opportunities!$Z$3:$Z$502,0)))) | J13: =IFERROR(SMALL(Opportunities!$Z$3:$Z$502,8),"")
A14: =IF($J14="","",9) | B14: =IF($J14="","",INDEX(Opportunities!$Y$3:$Y$502,MATCH($J14,Opportunities!$Z$3:$Z$502,0))) | C14: =IF($J14="","",INDEX(Opportunities!$A$3:$A$502,MATCH($J14,Opportunities!$Z$3:$Z$502,0))) | D14: =IF($J14="","",INDEX(Opportunities!$B$3:$B$502,MATCH($J14,Opportunities!$Z$3:$Z$502,0))) | E14: =IF($J14="","",INDEX(Opportunities!$C$3:$C$502,MATCH($J14,Opportunities!$Z$3:$Z$502,0))) | F14: =IF($J14="","",IF(INDEX(Opportunities!$D$3:$D$502,MATCH($J14,Opportunities!$Z$3:$Z$502,0))="","(no owner)",INDEX(Opportunities!$D$3:$D$502,MATCH($J14,Opportunities!$Z$3:$Z$502,0)))) | G14: =IF($J14="","",IF(INDEX(Opportunities!$L$3:$L$502,MATCH($J14,Opportunities!$Z$3:$Z$502,0))="","(add a next action)",INDEX(Opportunities!$L$3:$L$502,MATCH($J14,Opportunities!$Z$3:$Z$502,0)))) | H14: =IF($J14="","",IF(INDEX(Opportunities!$M$3:$M$502,MATCH($J14,Opportunities!$Z$3:$Z$502,0))="","",INDEX(Opportunities!$M$3:$M$502,MATCH($J14,Opportunities!$Z$3:$Z$502,0)))) | I14: =IF($J14="","",IF(INDEX(Opportunities!$P$3:$P$502,MATCH($J14,Opportunities!$Z$3:$Z$502,0))="","",INDEX(Opportunities!$P$3:$P$502,MATCH($J14,Opportunities!$Z$3:$Z$502,0)))) | J14: =IFERROR(SMALL(Opportunities!$Z$3:$Z$502,9),"")
A15: =IF($J15="","",10) | B15: =IF($J15="","",INDEX(Opportunities!$Y$3:$Y$502,MATCH($J15,Opportunities!$Z$3:$Z$502,0))) | C15: =IF($J15="","",INDEX(Opportunities!$A$3:$A$502,MATCH($J15,Opportunities!$Z$3:$Z$502,0))) | D15: =IF($J15="","",INDEX(Opportunities!$B$3:$B$502,MATCH($J15,Opportunities!$Z$3:$Z$502,0))) | E15: =IF($J15="","",INDEX(Opportunities!$C$3:$C$502,MATCH($J15,Opportunities!$Z$3:$Z$502,0))) | F15: =IF($J15="","",IF(INDEX(Opportunities!$D$3:$D$502,MATCH($J15,Opportunities!$Z$3:$Z$502,0))="","(no owner)",INDEX(Opportunities!$D$3:$D$502,MATCH($J15,Opportunities!$Z$3:$Z$502,0)))) | G15: =IF($J15="","",IF(INDEX(Opportunities!$L$3:$L$502,MATCH($J15,Opportunities!$Z$3:$Z$502,0))="","(add a next action)",INDEX(Opportunities!$L$3:$L$502,MATCH($J15,Opportunities!$Z$3:$Z$502,0)))) | H15: =IF($J15="","",IF(INDEX(Opportunities!$M$3:$M$502,MATCH($J15,Opportunities!$Z$3:$Z$502,0))="","",INDEX(Opportunities!$M$3:$M$502,MATCH($J15,Opportunities!$Z$3:$Z$502,0)))) | I15: =IF($J15="","",IF(INDEX(Opportunities!$P$3:$P$502,MATCH($J15,Opportunities!$Z$3:$Z$502,0))="","",INDEX(Opportunities!$P$3:$P$502,MATCH($J15,Opportunities!$Z$3:$Z$502,0)))) | J15: =IFERROR(SMALL(Opportunities!$Z$3:$Z$502,10),"")
A16: =IF($J16="","",11) | B16: =IF($J16="","",INDEX(Opportunities!$Y$3:$Y$502,MATCH($J16,Opportunities!$Z$3:$Z$502,0))) | C16: =IF($J16="","",INDEX(Opportunities!$A$3:$A$502,MATCH($J16,Opportunities!$Z$3:$Z$502,0))) | D16: =IF($J16="","",INDEX(Opportunities!$B$3:$B$502,MATCH($J16,Opportunities!$Z$3:$Z$502,0))) | E16: =IF($J16="","",INDEX(Opportunities!$C$3:$C$502,MATCH($J16,Opportunities!$Z$3:$Z$502,0))) | F16: =IF($J16="","",IF(INDEX(Opportunities!$D$3:$D$502,MATCH($J16,Opportunities!$Z$3:$Z$502,0))="","(no owner)",INDEX(Opportunities!$D$3:$D$502,MATCH($J16,Opportunities!$Z$3:$Z$502,0)))) | G16: =IF($J16="","",IF(INDEX(Opportunities!$L$3:$L$502,MATCH($J16,Opportunities!$Z$3:$Z$502,0))="","(add a next action)",INDEX(Opportunities!$L$3:$L$502,MATCH($J16,Opportunities!$Z$3:$Z$502,0)))) | H16: =IF($J16="","",IF(INDEX(Opportunities!$M$3:$M$502,MATCH($J16,Opportunities!$Z$3:$Z$502,0))="","",INDEX(Opportunities!$M$3:$M$502,MATCH($J16,Opportunities!$Z$3:$Z$502,0)))) | I16: =IF($J16="","",IF(INDEX(Opportunities!$P$3:$P$502,MATCH($J16,Opportunities!$Z$3:$Z$502,0))="","",INDEX(Opportunities!$P$3:$P$502,MATCH($J16,Opportunities!$Z$3:$Z$502,0)))) | J16: =IFERROR(SMALL(Opportunities!$Z$3:$Z$502,11),"")
A17: =IF($J17="","",12) | B17: =IF($J17="","",INDEX(Opportunities!$Y$3:$Y$502,MATCH($J17,Opportunities!$Z$3:$Z$502,0))) | C17: =IF($J17="","",INDEX(Opportunities!$A$3:$A$502,MATCH($J17,Opportunities!$Z$3:$Z$502,0))) | D17: =IF($J17="","",INDEX(Opportunities!$B$3:$B$502,MATCH($J17,Opportunities!$Z$3:$Z$502,0))) | E17: =IF($J17="","",INDEX(Opportunities!$C$3:$C$502,MATCH($J17,Opportunities!$Z$3:$Z$502,0))) | F17: =IF($J17="","",IF(INDEX(Opportunities!$D$3:$D$502,MATCH($J17,Opportunities!$Z$3:$Z$502,0))="","(no owner)",INDEX(Opportunities!$D$3:$D$502,MATCH($J17,Opportunities!$Z$3:$Z$502,0)))) | G17: =IF($J17="","",IF(INDEX(Opportunities!$L$3:$L$502,MATCH($J17,Opportunities!$Z$3:$Z$502,0))="","(add a next action)",INDEX(Opportunities!$L$3:$L$502,MATCH($J17,Opportunities!$Z$3:$Z$502,0)))) | H17: =IF($J17="","",IF(INDEX(Opportunities!$M$3:$M$502,MATCH($J17,Opportunities!$Z$3:$Z$502,0))="","",INDEX(Opportunities!$M$3:$M$502,MATCH($J17,Opportunities!$Z$3:$Z$502,0)))) | I17: =IF($J17="","",IF(INDEX(Opportunities!$P$3:$P$502,MATCH($J17,Opportunities!$Z$3:$Z$502,0))="","",INDEX(Opportunities!$P$3:$P$502,MATCH($J17,Opportunities!$Z$3:$Z$502,0)))) | J17: =IFERROR(SMALL(Opportunities!$Z$3:$Z$502,12),"")
A18: =IF($J18="","",13) | B18: =IF($J18="","",INDEX(Opportunities!$Y$3:$Y$502,MATCH($J18,Opportunities!$Z$3:$Z$502,0))) | C18: =IF($J18="","",INDEX(Opportunities!$A$3:$A$502,MATCH($J18,Opportunities!$Z$3:$Z$502,0))) | D18: =IF($J18="","",INDEX(Opportunities!$B$3:$B$502,MATCH($J18,Opportunities!$Z$3:$Z$502,0))) | E18: =IF($J18="","",INDEX(Opportunities!$C$3:$C$502,MATCH($J18,Opportunities!$Z$3:$Z$502,0))) | F18: =IF($J18="","",IF(INDEX(Opportunities!$D$3:$D$502,MATCH($J18,Opportunities!$Z$3:$Z$502,0))="","(no owner)",INDEX(Opportunities!$D$3:$D$502,MATCH($J18,Opportunities!$Z$3:$Z$502,0)))) | G18: =IF($J18="","",IF(INDEX(Opportunities!$L$3:$L$502,MATCH($J18,Opportunities!$Z$3:$Z$502,0))="","(add a next action)",INDEX(Opportunities!$L$3:$L$502,MATCH($J18,Opportunities!$Z$3:$Z$502,0)))) | H18: =IF($J18="","",IF(INDEX(Opportunities!$M$3:$M$502,MATCH($J18,Opportunities!$Z$3:$Z$502,0))="","",INDEX(Opportunities!$M$3:$M$502,MATCH($J18,Opportunities!$Z$3:$Z$502,0)))) | I18: =IF($J18="","",IF(INDEX(Opportunities!$P$3:$P$502,MATCH($J18,Opportunities!$Z$3:$Z$502,0))="","",INDEX(Opportunities!$P$3:$P$502,MATCH($J18,Opportunities!$Z$3:$Z$502,0)))) | J18: =IFERROR(SMALL(Opportunities!$Z$3:$Z$502,13),"")
A19: =IF($J19="","",14) | B19: =IF($J19="","",INDEX(Opportunities!$Y$3:$Y$502,MATCH($J19,Opportunities!$Z$3:$Z$502,0))) | C19: =IF($J19="","",INDEX(Opportunities!$A$3:$A$502,MATCH($J19,Opportunities!$Z$3:$Z$502,0))) | D19: =IF($J19="","",INDEX(Opportunities!$B$3:$B$502,MATCH($J19,Opportunities!$Z$3:$Z$502,0))) | E19: =IF($J19="","",INDEX(Opportunities!$C$3:$C$502,MATCH($J19,Opportunities!$Z$3:$Z$502,0))) | F19: =IF($J19="","",IF(INDEX(Opportunities!$D$3:$D$502,MATCH($J19,Opportunities!$Z$3:$Z$502,0))="","(no owner)",INDEX(Opportunities!$D$3:$D$502,MATCH($J19,Opportunities!$Z$3:$Z$502,0)))) | G19: =IF($J19="","",IF(INDEX(Opportunities!$L$3:$L$502,MATCH($J19,Opportunities!$Z$3:$Z$502,0))="","(add a next action)",INDEX(Opportunities!$L$3:$L$502,MATCH($J19,Opportunities!$Z$3:$Z$502,0)))) | H19: =IF($J19="","",IF(INDEX(Opportunities!$M$3:$M$502,MATCH($J19,Opportunities!$Z$3:$Z$502,0))="","",INDEX(Opportunities!$M$3:$M$502,MATCH($J19,Opportunities!$Z$3:$Z$502,0)))) | I19: =IF($J19="","",IF(INDEX(Opportunities!$P$3:$P$502,MATCH($J19,Opportunities!$Z$3:$Z$502,0))="","",INDEX(Opportunities!$P$3:$P$502,MATCH($J19,Opportunities!$Z$3:$Z$502,0)))) | J19: =IFERROR(SMALL(Opportunities!$Z$3:$Z$502,14),"")
A20: =IF($J20="","",15) | B20: =IF($J20="","",INDEX(Opportunities!$Y$3:$Y$502,MATCH($J20,Opportunities!$Z$3:$Z$502,0))) | C20: =IF($J20="","",INDEX(Opportunities!$A$3:$A$502,MATCH($J20,Opportunities!$Z$3:$Z$502,0))) | D20: =IF($J20="","",INDEX(Opportunities!$B$3:$B$502,MATCH($J20,Opportunities!$Z$3:$Z$502,0))) | E20: =IF($J20="","",INDEX(Opportunities!$C$3:$C$502,MATCH($J20,Opportunities!$Z$3:$Z$502,0))) | F20: =IF($J20="","",IF(INDEX(Opportunities!$D$3:$D$502,MATCH($J20,Opportunities!$Z$3:$Z$502,0))="","(no owner)",INDEX(Opportunities!$D$3:$D$502,MATCH($J20,Opportunities!$Z$3:$Z$502,0)))) | G20: =IF($J20="","",IF(INDEX(Opportunities!$L$3:$L$502,MATCH($J20,Opportunities!$Z$3:$Z$502,0))="","(add a next action)",INDEX(Opportunities!$L$3:$L$502,MATCH($J20,Opportunities!$Z$3:$Z$502,0)))) | H20: =IF($J20="","",IF(INDEX(Opportunities!$M$3:$M$502,MATCH($J20,Opportunities!$Z$3:$Z$502,0))="","",INDEX(Opportunities!$M$3:$M$502,MATCH($J20,Opportunities!$Z$3:$Z$502,0)))) | I20: =IF($J20="","",IF(INDEX(Opportunities!$P$3:$P$502,MATCH($J20,Opportunities!$Z$3:$Z$502,0))="","",INDEX(Opportunities!$P$3:$P$502,MATCH($J20,Opportunities!$Z$3:$Z$502,0)))) | J20: =IFERROR(SMALL(Opportunities!$Z$3:$Z$502,15),"")
A21: =IF($J21="","",16) | B21: =IF($J21="","",INDEX(Opportunities!$Y$3:$Y$502,MATCH($J21,Opportunities!$Z$3:$Z$502,0))) | C21: =IF($J21="","",INDEX(Opportunities!$A$3:$A$502,MATCH($J21,Opportunities!$Z$3:$Z$502,0))) | D21: =IF($J21="","",INDEX(Opportunities!$B$3:$B$502,MATCH($J21,Opportunities!$Z$3:$Z$502,0))) | E21: =IF($J21="","",INDEX(Opportunities!$C$3:$C$502,MATCH($J21,Opportunities!$Z$3:$Z$502,0))) | F21: =IF($J21="","",IF(INDEX(Opportunities!$D$3:$D$502,MATCH($J21,Opportunities!$Z$3:$Z$502,0))="","(no owner)",INDEX(Opportunities!$D$3:$D$502,MATCH($J21,Opportunities!$Z$3:$Z$502,0)))) | G21: =IF($J21="","",IF(INDEX(Opportunities!$L$3:$L$502,MATCH($J21,Opportunities!$Z$3:$Z$502,0))="","(add a next action)",INDEX(Opportunities!$L$3:$L$502,MATCH($J21,Opportunities!$Z$3:$Z$502,0)))) | H21: =IF($J21="","",IF(INDEX(Opportunities!$M$3:$M$502,MATCH($J21,Opportunities!$Z$3:$Z$502,0))="","",INDEX(Opportunities!$M$3:$M$502,MATCH($J21,Opportunities!$Z$3:$Z$502,0)))) | I21: =IF($J21="","",IF(INDEX(Opportunities!$P$3:$P$502,MATCH($J21,Opportunities!$Z$3:$Z$502,0))="","",INDEX(Opportunities!$P$3:$P$502,MATCH($J21,Opportunities!$Z$3:$Z$502,0)))) | J21: =IFERROR(SMALL(Opportunities!$Z$3:$Z$502,16),"")
A22: =IF($J22="","",17) | B22: =IF($J22="","",INDEX(Opportunities!$Y$3:$Y$502,MATCH($J22,Opportunities!$Z$3:$Z$502,0))) | C22: =IF($J22="","",INDEX(Opportunities!$A$3:$A$502,MATCH($J22,Opportunities!$Z$3:$Z$502,0))) | D22: =IF($J22="","",INDEX(Opportunities!$B$3:$B$502,MATCH($J22,Opportunities!$Z$3:$Z$502,0))) | E22: =IF($J22="","",INDEX(Opportunities!$C$3:$C$502,MATCH($J22,Opportunities!$Z$3:$Z$502,0))) | F22: =IF($J22="","",IF(INDEX(Opportunities!$D$3:$D$502,MATCH($J22,Opportunities!$Z$3:$Z$502,0))="","(no owner)",INDEX(Opportunities!$D$3:$D$502,MATCH($J22,Opportunities!$Z$3:$Z$502,0)))) | G22: =IF($J22="","",IF(INDEX(Opportunities!$L$3:$L$502,MATCH($J22,Opportunities!$Z$3:$Z$502,0))="","(add a next action)",INDEX(Opportunities!$L$3:$L$502,MATCH($J22,Opportunities!$Z$3:$Z$502,0)))) | H22: =IF($J22="","",IF(INDEX(Opportunities!$M$3:$M$502,MATCH($J22,Opportunities!$Z$3:$Z$502,0))="","",INDEX(Opportunities!$M$3:$M$502,MATCH($J22,Opportunities!$Z$3:$Z$502,0)))) | I22: =IF($J22="","",IF(INDEX(Opportunities!$P$3:$P$502,MATCH($J22,Opportunities!$Z$3:$Z$502,0))="","",INDEX(Opportunities!$P$3:$P$502,MATCH($J22,Opportunities!$Z$3:$Z$502,0)))) | J22: =IFERROR(SMALL(Opportunities!$Z$3:$Z$502,17),"")
A23: =IF($J23="","",18) | B23: =IF($J23="","",INDEX(Opportunities!$Y$3:$Y$502,MATCH($J23,Opportunities!$Z$3:$Z$502,0))) | C23: =IF($J23="","",INDEX(Opportunities!$A$3:$A$502,MATCH($J23,Opportunities!$Z$3:$Z$502,0))) | D23: =IF($J23="","",INDEX(Opportunities!$B$3:$B$502,MATCH($J23,Opportunities!$Z$3:$Z$502,0))) | E23: =IF($J23="","",INDEX(Opportunities!$C$3:$C$502,MATCH($J23,Opportunities!$Z$3:$Z$502,0))) | F23: =IF($J23="","",IF(INDEX(Opportunities!$D$3:$D$502,MATCH($J23,Opportunities!$Z$3:$Z$502,0))="","(no owner)",INDEX(Opportunities!$D$3:$D$502,MATCH($J23,Opportunities!$Z$3:$Z$502,0)))) | G23: =IF($J23="","",IF(INDEX(Opportunities!$L$3:$L$502,MATCH($J23,Opportunities!$Z$3:$Z$502,0))="","(add a next action)",INDEX(Opportunities!$L$3:$L$502,MATCH($J23,Opportunities!$Z$3:$Z$502,0)))) | H23: =IF($J23="","",IF(INDEX(Opportunities!$M$3:$M$502,MATCH($J23,Opportunities!$Z$3:$Z$502,0))="","",INDEX(Opportunities!$M$3:$M$502,MATCH($J23,Opportunities!$Z$3:$Z$502,0)))) | I23: =IF($J23="","",IF(INDEX(Opportunities!$P$3:$P$502,MATCH($J23,Opportunities!$Z$3:$Z$502,0))="","",INDEX(Opportunities!$P$3:$P$502,MATCH($J23,Opportunities!$Z$3:$Z$502,0)))) | J23: =IFERROR(SMALL(Opportunities!$Z$3:$Z$502,18),"")
A24: =IF($J24="","",19) | B24: =IF($J24="","",INDEX(Opportunities!$Y$3:$Y$502,MATCH($J24,Opportunities!$Z$3:$Z$502,0))) | C24: =IF($J24="","",INDEX(Opportunities!$A$3:$A$502,MATCH($J24,Opportunities!$Z$3:$Z$502,0))) | D24: =IF($J24="","",INDEX(Opportunities!$B$3:$B$502,MATCH($J24,Opportunities!$Z$3:$Z$502,0))) | E24: =IF($J24="","",INDEX(Opportunities!$C$3:$C$502,MATCH($J24,Opportunities!$Z$3:$Z$502,0))) | F24: =IF($J24="","",IF(INDEX(Opportunities!$D$3:$D$502,MATCH($J24,Opportunities!$Z$3:$Z$502,0))="","(no owner)",INDEX(Opportunities!$D$3:$D$502,MATCH($J24,Opportunities!$Z$3:$Z$502,0)))) | G24: =IF($J24="","",IF(INDEX(Opportunities!$L$3:$L$502,MATCH($J24,Opportunities!$Z$3:$Z$502,0))="","(add a next action)",INDEX(Opportunities!$L$3:$L$502,MATCH($J24,Opportunities!$Z$3:$Z$502,0)))) | H24: =IF($J24="","",IF(INDEX(Opportunities!$M$3:$M$502,MATCH($J24,Opportunities!$Z$3:$Z$502,0))="","",INDEX(Opportunities!$M$3:$M$502,MATCH($J24,Opportunities!$Z$3:$Z$502,0)))) | I24: =IF($J24="","",IF(INDEX(Opportunities!$P$3:$P$502,MATCH($J24,Opportunities!$Z$3:$Z$502,0))="","",INDEX(Opportunities!$P$3:$P$502,MATCH($J24,Opportunities!$Z$3:$Z$502,0)))) | J24: =IFERROR(SMALL(Opportunities!$Z$3:$Z$502,19),"")
A25: =IF($J25="","",20) | B25: =IF($J25="","",INDEX(Opportunities!$Y$3:$Y$502,MATCH($J25,Opportunities!$Z$3:$Z$502,0))) | C25: =IF($J25="","",INDEX(Opportunities!$A$3:$A$502,MATCH($J25,Opportunities!$Z$3:$Z$502,0))) | D25: =IF($J25="","",INDEX(Opportunities!$B$3:$B$502,MATCH($J25,Opportunities!$Z$3:$Z$502,0))) | E25: =IF($J25="","",INDEX(Opportunities!$C$3:$C$502,MATCH($J25,Opportunities!$Z$3:$Z$502,0))) | F25: =IF($J25="","",IF(INDEX(Opportunities!$D$3:$D$502,MATCH($J25,Opportunities!$Z$3:$Z$502,0))="","(no owner)",INDEX(Opportunities!$D$3:$D$502,MATCH($J25,Opportunities!$Z$3:$Z$502,0)))) | G25: =IF($J25="","",IF(INDEX(Opportunities!$L$3:$L$502,MATCH($J25,Opportunities!$Z$3:$Z$502,0))="","(add a next action)",INDEX(Opportunities!$L$3:$L$502,MATCH($J25,Opportunities!$Z$3:$Z$502,0)))) | H25: =IF($J25="","",IF(INDEX(Opportunities!$M$3:$M$502,MATCH($J25,Opportunities!$Z$3:$Z$502,0))="","",INDEX(Opportunities!$M$3:$M$502,MATCH($J25,Opportunities!$Z$3:$Z$502,0)))) | I25: =IF($J25="","",IF(INDEX(Opportunities!$P$3:$P$502,MATCH($J25,Opportunities!$Z$3:$Z$502,0))="","",INDEX(Opportunities!$P$3:$P$502,MATCH($J25,Opportunities!$Z$3:$Z$502,0)))) | J25: =IFERROR(SMALL(Opportunities!$Z$3:$Z$502,20),"")
A26: =IF($J26="","",21) | B26: =IF($J26="","",INDEX(Opportunities!$Y$3:$Y$502,MATCH($J26,Opportunities!$Z$3:$Z$502,0))) | C26: =IF($J26="","",INDEX(Opportunities!$A$3:$A$502,MATCH($J26,Opportunities!$Z$3:$Z$502,0))) | D26: =IF($J26="","",INDEX(Opportunities!$B$3:$B$502,MATCH($J26,Opportunities!$Z$3:$Z$502,0))) | E26: =IF($J26="","",INDEX(Opportunities!$C$3:$C$502,MATCH($J26,Opportunities!$Z$3:$Z$502,0))) | F26: =IF($J26="","",IF(INDEX(Opportunities!$D$3:$D$502,MATCH($J26,Opportunities!$Z$3:$Z$502,0))="","(no owner)",INDEX(Opportunities!$D$3:$D$502,MATCH($J26,Opportunities!$Z$3:$Z$502,0)))) | G26: =IF($J26="","",IF(INDEX(Opportunities!$L$3:$L$502,MATCH($J26,Opportunities!$Z$3:$Z$502,0))="","(add a next action)",INDEX(Opportunities!$L$3:$L$502,MATCH($J26,Opportunities!$Z$3:$Z$502,0)))) | H26: =IF($J26="","",IF(INDEX(Opportunities!$M$3:$M$502,MATCH($J26,Opportunities!$Z$3:$Z$502,0))="","",INDEX(Opportunities!$M$3:$M$502,MATCH($J26,Opportunities!$Z$3:$Z$502,0)))) | I26: =IF($J26="","",IF(INDEX(Opportunities!$P$3:$P$502,MATCH($J26,Opportunities!$Z$3:$Z$502,0))="","",INDEX(Opportunities!$P$3:$P$502,MATCH($J26,Opportunities!$Z$3:$Z$502,0)))) | J26: =IFERROR(SMALL(Opportunities!$Z$3:$Z$502,21),"")
A27: =IF($J27="","",22) | B27: =IF($J27="","",INDEX(Opportunities!$Y$3:$Y$502,MATCH($J27,Opportunities!$Z$3:$Z$502,0))) | C27: =IF($J27="","",INDEX(Opportunities!$A$3:$A$502,MATCH($J27,Opportunities!$Z$3:$Z$502,0))) | D27: =IF($J27="","",INDEX(Opportunities!$B$3:$B$502,MATCH($J27,Opportunities!$Z$3:$Z$502,0))) | E27: =IF($J27="","",INDEX(Opportunities!$C$3:$C$502,MATCH($J27,Opportunities!$Z$3:$Z$502,0))) | F27: =IF($J27="","",IF(INDEX(Opportunities!$D$3:$D$502,MATCH($J27,Opportunities!$Z$3:$Z$502,0))="","(no owner)",INDEX(Opportunities!$D$3:$D$502,MATCH($J27,Opportunities!$Z$3:$Z$502,0)))) | G27: =IF($J27="","",IF(INDEX(Opportunities!$L$3:$L$502,MATCH($J27,Opportunities!$Z$3:$Z$502,0))="","(add a next action)",INDEX(Opportunities!$L$3:$L$502,MATCH($J27,Opportunities!$Z$3:$Z$502,0)))) | H27: =IF($J27="","",IF(INDEX(Opportunities!$M$3:$M$502,MATCH($J27,Opportunities!$Z$3:$Z$502,0))="","",INDEX(Opportunities!$M$3:$M$502,MATCH($J27,Opportunities!$Z$3:$Z$502,0)))) | I27: =IF($J27="","",IF(INDEX(Opportunities!$P$3:$P$502,MATCH($J27,Opportunities!$Z$3:$Z$502,0))="","",INDEX(Opportunities!$P$3:$P$502,MATCH($J27,Opportunities!$Z$3:$Z$502,0)))) | J27: =IFERROR(SMALL(Opportunities!$Z$3:$Z$502,22),"")
A28: =IF($J28="","",23) | B28: =IF($J28="","",INDEX(Opportunities!$Y$3:$Y$502,MATCH($J28,Opportunities!$Z$3:$Z$502,0))) | C28: =IF($J28="","",INDEX(Opportunities!$A$3:$A$502,MATCH($J28,Opportunities!$Z$3:$Z$502,0))) | D28: =IF($J28="","",INDEX(Opportunities!$B$3:$B$502,MATCH($J28,Opportunities!$Z$3:$Z$502,0))) | E28: =IF($J28="","",INDEX(Opportunities!$C$3:$C$502,MATCH($J28,Opportunities!$Z$3:$Z$502,0))) | F28: =IF($J28="","",IF(INDEX(Opportunities!$D$3:$D$502,MATCH($J28,Opportunities!$Z$3:$Z$502,0))="","(no owner)",INDEX(Opportunities!$D$3:$D$502,MATCH($J28,Opportunities!$Z$3:$Z$502,0)))) | G28: =IF($J28="","",IF(INDEX(Opportunities!$L$3:$L$502,MATCH($J28,Opportunities!$Z$3:$Z$502,0))="","(add a next action)",INDEX(Opportunities!$L$3:$L$502,MATCH($J28,Opportunities!$Z$3:$Z$502,0)))) | H28: =IF($J28="","",IF(INDEX(Opportunities!$M$3:$M$502,MATCH($J28,Opportunities!$Z$3:$Z$502,0))="","",INDEX(Opportunities!$M$3:$M$502,MATCH($J28,Opportunities!$Z$3:$Z$502,0)))) | I28: =IF($J28="","",IF(INDEX(Opportunities!$P$3:$P$502,MATCH($J28,Opportunities!$Z$3:$Z$502,0))="","",INDEX(Opportunities!$P$3:$P$502,MATCH($J28,Opportunities!$Z$3:$Z$502,0)))) | J28: =IFERROR(SMALL(Opportunities!$Z$3:$Z$502,23),"")
A29: =IF($J29="","",24) | B29: =IF($J29="","",INDEX(Opportunities!$Y$3:$Y$502,MATCH($J29,Opportunities!$Z$3:$Z$502,0))) | C29: =IF($J29="","",INDEX(Opportunities!$A$3:$A$502,MATCH($J29,Opportunities!$Z$3:$Z$502,0))) | D29: =IF($J29="","",INDEX(Opportunities!$B$3:$B$502,MATCH($J29,Opportunities!$Z$3:$Z$502,0))) | E29: =IF($J29="","",INDEX(Opportunities!$C$3:$C$502,MATCH($J29,Opportunities!$Z$3:$Z$502,0))) | F29: =IF($J29="","",IF(INDEX(Opportunities!$D$3:$D$502,MATCH($J29,Opportunities!$Z$3:$Z$502,0))="","(no owner)",INDEX(Opportunities!$D$3:$D$502,MATCH($J29,Opportunities!$Z$3:$Z$502,0)))) | G29: =IF($J29="","",IF(INDEX(Opportunities!$L$3:$L$502,MATCH($J29,Opportunities!$Z$3:$Z$502,0))="","(add a next action)",INDEX(Opportunities!$L$3:$L$502,MATCH($J29,Opportunities!$Z$3:$Z$502,0)))) | H29: =IF($J29="","",IF(INDEX(Opportunities!$M$3:$M$502,MATCH($J29,Opportunities!$Z$3:$Z$502,0))="","",INDEX(Opportunities!$M$3:$M$502,MATCH($J29,Opportunities!$Z$3:$Z$502,0)))) | I29: =IF($J29="","",IF(INDEX(Opportunities!$P$3:$P$502,MATCH($J29,Opportunities!$Z$3:$Z$502,0))="","",INDEX(Opportunities!$P$3:$P$502,MATCH($J29,Opportunities!$Z$3:$Z$502,0)))) | J29: =IFERROR(SMALL(Opportunities!$Z$3:$Z$502,24),"")
A30: =IF($J30="","",25) | B30: =IF($J30="","",INDEX(Opportunities!$Y$3:$Y$502,MATCH($J30,Opportunities!$Z$3:$Z$502,0))) | C30: =IF($J30="","",INDEX(Opportunities!$A$3:$A$502,MATCH($J30,Opportunities!$Z$3:$Z$502,0))) | D30: =IF($J30="","",INDEX(Opportunities!$B$3:$B$502,MATCH($J30,Opportunities!$Z$3:$Z$502,0))) | E30: =IF($J30="","",INDEX(Opportunities!$C$3:$C$502,MATCH($J30,Opportunities!$Z$3:$Z$502,0))) | F30: =IF($J30="","",IF(INDEX(Opportunities!$D$3:$D$502,MATCH($J30,Opportunities!$Z$3:$Z$502,0))="","(no owner)",INDEX(Opportunities!$D$3:$D$502,MATCH($J30,Opportunities!$Z$3:$Z$502,0)))) | G30: =IF($J30="","",IF(INDEX(Opportunities!$L$3:$L$502,MATCH($J30,Opportunities!$Z$3:$Z$502,0))="","(add a next action)",INDEX(Opportunities!$L$3:$L$502,MATCH($J30,Opportunities!$Z$3:$Z$502,0)))) | H30: =IF($J30="","",IF(INDEX(Opportunities!$M$3:$M$502,MATCH($J30,Opportunities!$Z$3:$Z$502,0))="","",INDEX(Opportunities!$M$3:$M$502,MATCH($J30,Opportunities!$Z$3:$Z$502,0)))) | I30: =IF($J30="","",IF(INDEX(Opportunities!$P$3:$P$502,MATCH($J30,Opportunities!$Z$3:$Z$502,0))="","",INDEX(Opportunities!$P$3:$P$502,MATCH($J30,Opportunities!$Z$3:$Z$502,0)))) | J30: =IFERROR(SMALL(Opportunities!$Z$3:$Z$502,25),"")
A31: =IF($J31="","",26) | B31: =IF($J31="","",INDEX(Opportunities!$Y$3:$Y$502,MATCH($J31,Opportunities!$Z$3:$Z$502,0))) | C31: =IF($J31="","",INDEX(Opportunities!$A$3:$A$502,MATCH($J31,Opportunities!$Z$3:$Z$502,0))) | D31: =IF($J31="","",INDEX(Opportunities!$B$3:$B$502,MATCH($J31,Opportunities!$Z$3:$Z$502,0))) | E31: =IF($J31="","",INDEX(Opportunities!$C$3:$C$502,MATCH($J31,Opportunities!$Z$3:$Z$502,0))) | F31: =IF($J31="","",IF(INDEX(Opportunities!$D$3:$D$502,MATCH($J31,Opportunities!$Z$3:$Z$502,0))="","(no owner)",INDEX(Opportunities!$D$3:$D$502,MATCH($J31,Opportunities!$Z$3:$Z$502,0)))) | G31: =IF($J31="","",IF(INDEX(Opportunities!$L$3:$L$502,MATCH($J31,Opportunities!$Z$3:$Z$502,0))="","(add a next action)",INDEX(Opportunities!$L$3:$L$502,MATCH($J31,Opportunities!$Z$3:$Z$502,0)))) | H31: =IF($J31="","",IF(INDEX(Opportunities!$M$3:$M$502,MATCH($J31,Opportunities!$Z$3:$Z$502,0))="","",INDEX(Opportunities!$M$3:$M$502,MATCH($J31,Opportunities!$Z$3:$Z$502,0)))) | I31: =IF($J31="","",IF(INDEX(Opportunities!$P$3:$P$502,MATCH($J31,Opportunities!$Z$3:$Z$502,0))="","",INDEX(Opportunities!$P$3:$P$502,MATCH($J31,Opportunities!$Z$3:$Z$502,0)))) | J31: =IFERROR(SMALL(Opportunities!$Z$3:$Z$502,26),"")
A32: =IF($J32="","",27) | B32: =IF($J32="","",INDEX(Opportunities!$Y$3:$Y$502,MATCH($J32,Opportunities!$Z$3:$Z$502,0))) | C32: =IF($J32="","",INDEX(Opportunities!$A$3:$A$502,MATCH($J32,Opportunities!$Z$3:$Z$502,0))) | D32: =IF($J32="","",INDEX(Opportunities!$B$3:$B$502,MATCH($J32,Opportunities!$Z$3:$Z$502,0))) | E32: =IF($J32="","",INDEX(Opportunities!$C$3:$C$502,MATCH($J32,Opportunities!$Z$3:$Z$502,0))) | F32: =IF($J32="","",IF(INDEX(Opportunities!$D$3:$D$502,MATCH($J32,Opportunities!$Z$3:$Z$502,0))="","(no owner)",INDEX(Opportunities!$D$3:$D$502,MATCH($J32,Opportunities!$Z$3:$Z$502,0)))) | G32: =IF($J32="","",IF(INDEX(Opportunities!$L$3:$L$502,MATCH($J32,Opportunities!$Z$3:$Z$502,0))="","(add a next action)",INDEX(Opportunities!$L$3:$L$502,MATCH($J32,Opportunities!$Z$3:$Z$502,0)))) | H32: =IF($J32="","",IF(INDEX(Opportunities!$M$3:$M$502,MATCH($J32,Opportunities!$Z$3:$Z$502,0))="","",INDEX(Opportunities!$M$3:$M$502,MATCH($J32,Opportunities!$Z$3:$Z$502,0)))) | I32: =IF($J32="","",IF(INDEX(Opportunities!$P$3:$P$502,MATCH($J32,Opportunities!$Z$3:$Z$502,0))="","",INDEX(Opportunities!$P$3:$P$502,MATCH($J32,Opportunities!$Z$3:$Z$502,0)))) | J32: =IFERROR(SMALL(Opportunities!$Z$3:$Z$502,27),"")
A33: =IF($J33="","",28) | B33: =IF($J33="","",INDEX(Opportunities!$Y$3:$Y$502,MATCH($J33,Opportunities!$Z$3:$Z$502,0))) | C33: =IF($J33="","",INDEX(Opportunities!$A$3:$A$502,MATCH($J33,Opportunities!$Z$3:$Z$502,0))) | D33: =IF($J33="","",INDEX(Opportunities!$B$3:$B$502,MATCH($J33,Opportunities!$Z$3:$Z$502,0))) | E33: =IF($J33="","",INDEX(Opportunities!$C$3:$C$502,MATCH($J33,Opportunities!$Z$3:$Z$502,0))) | F33: =IF($J33="","",IF(INDEX(Opportunities!$D$3:$D$502,MATCH($J33,Opportunities!$Z$3:$Z$502,0))="","(no owner)",INDEX(Opportunities!$D$3:$D$502,MATCH($J33,Opportunities!$Z$3:$Z$502,0)))) | G33: =IF($J33="","",IF(INDEX(Opportunities!$L$3:$L$502,MATCH($J33,Opportunities!$Z$3:$Z$502,0))="","(add a next action)",INDEX(Opportunities!$L$3:$L$502,MATCH($J33,Opportunities!$Z$3:$Z$502,0)))) | H33: =IF($J33="","",IF(INDEX(Opportunities!$M$3:$M$502,MATCH($J33,Opportunities!$Z$3:$Z$502,0))="","",INDEX(Opportunities!$M$3:$M$502,MATCH($J33,Opportunities!$Z$3:$Z$502,0)))) | I33: =IF($J33="","",IF(INDEX(Opportunities!$P$3:$P$502,MATCH($J33,Opportunities!$Z$3:$Z$502,0))="","",INDEX(Opportunities!$P$3:$P$502,MATCH($J33,Opportunities!$Z$3:$Z$502,0)))) | J33: =IFERROR(SMALL(Opportunities!$Z$3:$Z$502,28),"")
A34: =IF($J34="","",29) | B34: =IF($J34="","",INDEX(Opportunities!$Y$3:$Y$502,MATCH($J34,Opportunities!$Z$3:$Z$502,0))) | C34: =IF($J34="","",INDEX(Opportunities!$A$3:$A$502,MATCH($J34,Opportunities!$Z$3:$Z$502,0))) | D34: =IF($J34="","",INDEX(Opportunities!$B$3:$B$502,MATCH($J34,Opportunities!$Z$3:$Z$502,0))) | E34: =IF($J34="","",INDEX(Opportunities!$C$3:$C$502,MATCH($J34,Opportunities!$Z$3:$Z$502,0))) | F34: =IF($J34="","",IF(INDEX(Opportunities!$D$3:$D$502,MATCH($J34,Opportunities!$Z$3:$Z$502,0))="","(no owner)",INDEX(Opportunities!$D$3:$D$502,MATCH($J34,Opportunities!$Z$3:$Z$502,0)))) | G34: =IF($J34="","",IF(INDEX(Opportunities!$L$3:$L$502,MATCH($J34,Opportunities!$Z$3:$Z$502,0))="","(add a next action)",INDEX(Opportunities!$L$3:$L$502,MATCH($J34,Opportunities!$Z$3:$Z$502,0)))) | H34: =IF($J34="","",IF(INDEX(Opportunities!$M$3:$M$502,MATCH($J34,Opportunities!$Z$3:$Z$502,0))="","",INDEX(Opportunities!$M$3:$M$502,MATCH($J34,Opportunities!$Z$3:$Z$502,0)))) | I34: =IF($J34="","",IF(INDEX(Opportunities!$P$3:$P$502,MATCH($J34,Opportunities!$Z$3:$Z$502,0))="","",INDEX(Opportunities!$P$3:$P$502,MATCH($J34,Opportunities!$Z$3:$Z$502,0)))) | J34: =IFERROR(SMALL(Opportunities!$Z$3:$Z$502,29),"")
A35: =IF($J35="","",30) | B35: =IF($J35="","",INDEX(Opportunities!$Y$3:$Y$502,MATCH($J35,Opportunities!$Z$3:$Z$502,0))) | C35: =IF($J35="","",INDEX(Opportunities!$A$3:$A$502,MATCH($J35,Opportunities!$Z$3:$Z$502,0))) | D35: =IF($J35="","",INDEX(Opportunities!$B$3:$B$502,MATCH($J35,Opportunities!$Z$3:$Z$502,0))) | E35: =IF($J35="","",INDEX(Opportunities!$C$3:$C$502,MATCH($J35,Opportunities!$Z$3:$Z$502,0))) | F35: =IF($J35="","",IF(INDEX(Opportunities!$D$3:$D$502,MATCH($J35,Opportunities!$Z$3:$Z$502,0))="","(no owner)",INDEX(Opportunities!$D$3:$D$502,MATCH($J35,Opportunities!$Z$3:$Z$502,0)))) | G35: =IF($J35="","",IF(INDEX(Opportunities!$L$3:$L$502,MATCH($J35,Opportunities!$Z$3:$Z$502,0))="","(add a next action)",INDEX(Opportunities!$L$3:$L$502,MATCH($J35,Opportunities!$Z$3:$Z$502,0)))) | H35: =IF($J35="","",IF(INDEX(Opportunities!$M$3:$M$502,MATCH($J35,Opportunities!$Z$3:$Z$502,0))="","",INDEX(Opportunities!$M$3:$M$502,MATCH($J35,Opportunities!$Z$3:$Z$502,0)))) | I35: =IF($J35="","",IF(INDEX(Opportunities!$P$3:$P$502,MATCH($J35,Opportunities!$Z$3:$Z$502,0))="","",INDEX(Opportunities!$P$3:$P$502,MATCH($J35,Opportunities!$Z$3:$Z$502,0)))) | J35: =IFERROR(SMALL(Opportunities!$Z$3:$Z$502,30),"")
A37: 3–4 · Priority prospects, building paths and quick wins (from Companies)
A38: # | B38: Why it's here | C38: Company | D38: Fit | E38: Access | F38: Owner | G38: Next step | H38: Quadrant | I38: Last contact | J38: key
A39: =IF($J39="","",1) -> 1 | B39: =IF($J39="","",IF($J39<700000,"Priority: no deal yet",IF($J39<800000,"Building a path",IF($J39<900000,"Quick win for a need","Path candidate (space for one more)")))) -> Priority: no deal yet | C39: =IF($J39="","",INDEX(Companies!$A$3:$A$502,MATCH($J39,Companies!$AI$3:$AI$502,0))) -> Nordlys Logistics (example) | D39: =IF($J39="","",INDEX(Companies!$AC$3:$AC$502,MATCH($J39,Companies!$AI$3:$AI$502,0))) -> 6 | E39: =IF($J39="","",INDEX(Companies!$AD$3:$AD$502,MATCH($J39,Companies!$AI$3:$AI$502,0))) -> 2 | F39: =IF($J39="","",IF(INDEX(Companies!$F$3:$F$502,MATCH($J39,Companies!$AI$3:$AI$502,0))="","(no owner)",INDEX(Companies!$F$3:$F$502,MATCH($J39,Companies!$AI$3:$AI$502,0)))) -> A.K. (example) | G39: =IF($J39="","",IF($J39<700000,"Plan the first ask (partnership type cheat sheet) and create an opportunity",IF($J39<800000,IF(INDEX(Companies!$W$3:$W$502,MATCH($J39,Companies!$AI$3:$AI$502,0))="","(add a path action)",INDEX(Companies!$W$3:$W$502,MATCH($J39,Companies!$AI$3:$AI$502,0))),IF($J39<900000,"Need: "&INDEX(Companies!$U$3:$U$502,MATCH($J39,Companies!$AI$3:$AI$502,0)),"Decide whether to start a path")))) -> Plan the first ask (partnership type cheat sheet) and create an opportunity | H39: =IF($J39="","",INDEX(Companies!$AE$3:$AE$502,MATCH($J39,Companies!$AI$3:$AI$502,0))) -> Priority | I39: =IF($J39="","",IF(INDEX(Companies!$AF$3:$AF$502,MATCH($J39,Companies!$AI$3:$AI$502,0))="","",INDEX(Companies!$AF$3:$AF$502,MATCH($J39,Companies!$AI$3:$AI$502,0)))) | J39: =IFERROR(SMALL(Companies!$AI$3:$AI$502,1),"") -> 604200
A40: =IF($J40="","",2) -> 2 | B40: =IF($J40="","",IF($J40<700000,"Priority: no deal yet",IF($J40<800000,"Building a path",IF($J40<900000,"Quick win for a need","Path candidate (space for one more)")))) -> Building a path | C40: =IF($J40="","",INDEX(Companies!$A$3:$A$502,MATCH($J40,Companies!$AI$3:$AI$502,0))) -> MegaBrand A/S (example) | D40: =IF($J40="","",INDEX(Companies!$AC$3:$AC$502,MATCH($J40,Companies!$AI$3:$AI$502,0))) -> 7 | E40: =IF($J40="","",INDEX(Companies!$AD$3:$AD$502,MATCH($J40,Companies!$AI$3:$AI$502,0))) -> 1 | F40: =IF($J40="","",IF(INDEX(Companies!$F$3:$F$502,MATCH($J40,Companies!$AI$3:$AI$502,0))="","(no owner)",INDEX(Companies!$F$3:$F$502,MATCH($J40,Companies!$AI$3:$AI$502,0)))) -> M.S. (example) | G40: =IF($J40="","",IF($J40<700000,"Plan the first ask (partnership type cheat sheet) and create an opportunity",IF($J40<800000,IF(INDEX(Companies!$W$3:$W$502,MATCH($J40,Companies!$AI$3:$AI$502,0))="","(add a path action)",INDEX(Companies!$W$3:$W$502,MATCH($J40,Companies!$AI$3:$AI$502,0))),IF($J40<900000,"Need: "&INDEX(Companies!$U$3:$U$502,MATCH($J40,Companies!$AI$3:$AI$502,0)),"Decide whether to start a path")))) -> Ask board alumni network for an introduction | H40: =IF($J40="","",INDEX(Companies!$AE$3:$AE$502,MATCH($J40,Companies!$AI$3:$AI$502,0))) -> Build a Path | I40: =IF($J40="","",IF(INDEX(Companies!$AF$3:$AF$502,MATCH($J40,Companies!$AI$3:$AI$502,0))="","",INDEX(Companies!$AF$3:$AF$502,MATCH($J40,Companies!$AI$3:$AI$502,0)))) -> 46295 | J40: =IFERROR(SMALL(Companies!$AI$3:$AI$502,2),"") -> 700628.2
A41: =IF($J41="","",3) | B41: =IF($J41="","",IF($J41<700000,"Priority: no deal yet",IF($J41<800000,"Building a path",IF($J41<900000,"Quick win for a need","Path candidate (space for one more)")))) | C41: =IF($J41="","",INDEX(Companies!$A$3:$A$502,MATCH($J41,Companies!$AI$3:$AI$502,0))) | D41: =IF($J41="","",INDEX(Companies!$AC$3:$AC$502,MATCH($J41,Companies!$AI$3:$AI$502,0))) | E41: =IF($J41="","",INDEX(Companies!$AD$3:$AD$502,MATCH($J41,Companies!$AI$3:$AI$502,0))) | F41: =IF($J41="","",IF(INDEX(Companies!$F$3:$F$502,MATCH($J41,Companies!$AI$3:$AI$502,0))="","(no owner)",INDEX(Companies!$F$3:$F$502,MATCH($J41,Companies!$AI$3:$AI$502,0)))) | G41: =IF($J41="","",IF($J41<700000,"Plan the first ask (partnership type cheat sheet) and create an opportunity",IF($J41<800000,IF(INDEX(Companies!$W$3:$W$502,MATCH($J41,Companies!$AI$3:$AI$502,0))="","(add a path action)",INDEX(Companies!$W$3:$W$502,MATCH($J41,Companies!$AI$3:$AI$502,0))),IF($J41<900000,"Need: "&INDEX(Companies!$U$3:$U$502,MATCH($J41,Companies!$AI$3:$AI$502,0)),"Decide whether to start a path")))) | H41: =IF($J41="","",INDEX(Companies!$AE$3:$AE$502,MATCH($J41,Companies!$AI$3:$AI$502,0))) | I41: =IF($J41="","",IF(INDEX(Companies!$AF$3:$AF$502,MATCH($J41,Companies!$AI$3:$AI$502,0))="","",INDEX(Companies!$AF$3:$AF$502,MATCH($J41,Companies!$AI$3:$AI$502,0)))) | J41: =IFERROR(SMALL(Companies!$AI$3:$AI$502,3),"")
A42: =IF($J42="","",4) | B42: =IF($J42="","",IF($J42<700000,"Priority: no deal yet",IF($J42<800000,"Building a path",IF($J42<900000,"Quick win for a need","Path candidate (space for one more)")))) | C42: =IF($J42="","",INDEX(Companies!$A$3:$A$502,MATCH($J42,Companies!$AI$3:$AI$502,0))) | D42: =IF($J42="","",INDEX(Companies!$AC$3:$AC$502,MATCH($J42,Companies!$AI$3:$AI$502,0))) | E42: =IF($J42="","",INDEX(Companies!$AD$3:$AD$502,MATCH($J42,Companies!$AI$3:$AI$502,0))) | F42: =IF($J42="","",IF(INDEX(Companies!$F$3:$F$502,MATCH($J42,Companies!$AI$3:$AI$502,0))="","(no owner)",INDEX(Companies!$F$3:$F$502,MATCH($J42,Companies!$AI$3:$AI$502,0)))) | G42: =IF($J42="","",IF($J42<700000,"Plan the first ask (partnership type cheat sheet) and create an opportunity",IF($J42<800000,IF(INDEX(Companies!$W$3:$W$502,MATCH($J42,Companies!$AI$3:$AI$502,0))="","(add a path action)",INDEX(Companies!$W$3:$W$502,MATCH($J42,Companies!$AI$3:$AI$502,0))),IF($J42<900000,"Need: "&INDEX(Companies!$U$3:$U$502,MATCH($J42,Companies!$AI$3:$AI$502,0)),"Decide whether to start a path")))) | H42: =IF($J42="","",INDEX(Companies!$AE$3:$AE$502,MATCH($J42,Companies!$AI$3:$AI$502,0))) | I42: =IF($J42="","",IF(INDEX(Companies!$AF$3:$AF$502,MATCH($J42,Companies!$AI$3:$AI$502,0))="","",INDEX(Companies!$AF$3:$AF$502,MATCH($J42,Companies!$AI$3:$AI$502,0)))) | J42: =IFERROR(SMALL(Companies!$AI$3:$AI$502,4),"")
...

Sheet Dashboard
A1: Dashboard
A2: ="Semester: "&S_SemesterLabel&" ("&TEXT(S_SemStart,"d mmm yyyy")&" – "&TEXT(S_SemEnd,"d mmm yyyy")&") · counts and recorded amounts only" -> Semester: Example semester (13 Aug 2026 – 9 Feb 2027) · counts and recorded amounts only
A4: Matrix (companies) | D4: Won this semester
A5: Priority | B5: =COUNTIF(Companies!$AE$3:$AE$502,"Priority") -> 2 | D5: Company | E5: Type | F5: Agreed (DKK) | G5: Non-cash / in-kind | H5: Renewal date | I5: Satisfaction
A6: Build a Path | B6: =COUNTIF(Companies!$AE$3:$AE$502,"Build a Path") -> 1 | D6: =IF(COUNT(Opportunities!$AB$3:$AB$502)<1,"",IFERROR(IF(INDEX(Opportunities!$A$3:$A$502,MATCH(IFERROR(SMALL(Opportunities!$AB$3:$AB$502,1),""),Opportunities!$AB$3:$AB$502,0))="","",INDEX(Opportunities!$A$3:$A$502,MATCH(IFERROR(SMALL(Opportunities!$AB$3:$AB$502,1),""),Opportunities!$AB$3:$AB$502,0))),"")) -> Søby Foods (example) | E6: =IF(COUNT(Opportunities!$AB$3:$AB$502)<1,"",IFERROR(IF(INDEX(Opportunities!$B$3:$B$502,MATCH(IFERROR(SMALL(Opportunities!$AB$3:$AB$502,1),""),Opportunities!$AB$3:$AB$502,0))="","",INDEX(Opportunities!$B$3:$B$502,MATCH(IFERROR(SMALL(Opportunities!$AB$3:$AB$502,1),""),Opportunities!$AB$3:$AB$502,0))),"")) -> Event sponsor | F6: =IF(COUNT(Opportunities!$AB$3:$AB$502)<1,"",IFERROR(IF(INDEX(Opportunities!$J$3:$J$502,MATCH(IFERROR(SMALL(Opportunities!$AB$3:$AB$502,1),""),Opportunities!$AB$3:$AB$502,0))="","",INDEX(Opportunities!$J$3:$J$502,MATCH(IFERROR(SMALL(Opportunities!$AB$3:$AB$502,1),""),Opportunities!$AB$3:$AB$502,0))),"")) -> 8000 | G6: =IF(COUNT(Opportunities!$AB$3:$AB$502)<1,"",IFERROR(IF(INDEX(Opportunities!$K$3:$K$502,MATCH(IFERROR(SMALL(Opportunities!$AB$3:$AB$502,1),""),Opportunities!$AB$3:$AB$502,0))="","",INDEX(Opportunities!$K$3:$K$502,MATCH(IFERROR(SMALL(Opportunities!$AB$3:$AB$502,1),""),Opportunities!$AB$3:$AB$502,0))),"")) | H6: =IF(COUNT(Opportunities!$AB$3:$AB$502)<1,"",IFERROR(IF(INDEX(Opportunities!$P$3:$P$502,MATCH(IFERROR(SMALL(Opportunities!$AB$3:$AB$502,1),""),Opportunities!$AB$3:$AB$502,0))="","",INDEX(Opportunities!$P$3:$P$502,MATCH(IFERROR(SMALL(Opportunities!$AB$3:$AB$502,1),""),Opportunities!$AB$3:$AB$502,0))),"")) -> 46607 | I6: =IF(COUNT(Opportunities!$AB$3:$AB$502)<1,"",IFERROR(IF(INDEX(Opportunities!$Q$3:$Q$502,MATCH(IFERROR(SMALL(Opportunities!$AB$3:$AB$502,1),""),Opportunities!$AB$3:$AB$502,0))="","",INDEX(Opportunities!$Q$3:$Q$502,MATCH(IFERROR(SMALL(Opportunities!$AB$3:$AB$502,1),""),Opportunities!$AB$3:$AB$502,0))),"")) -> Unknown
A7: Quick Win | B7: =COUNTIF(Companies!$AE$3:$AE$502,"Quick Win") -> 2 | D7: =IF(COUNT(Opportunities!$AB$3:$AB$502)<2,"",IFERROR(IF(INDEX(Opportunities!$A$3:$A$502,MATCH(IFERROR(SMALL(Opportunities!$AB$3:$AB$502,2),""),Opportunities!$AB$3:$AB$502,0))="","",INDEX(Opportunities!$A$3:$A$502,MATCH(IFERROR(SMALL(Opportunities!$AB$3:$AB$502,2),""),Opportunities!$AB$3:$AB$502,0))),"")) | E7: =IF(COUNT(Opportunities!$AB$3:$AB$502)<2,"",IFERROR(IF(INDEX(Opportunities!$B$3:$B$502,MATCH(IFERROR(SMALL(Opportunities!$AB$3:$AB$502,2),""),Opportunities!$AB$3:$AB$502,0))="","",INDEX(Opportunities!$B$3:$B$502,MATCH(IFERROR(SMALL(Opportunities!$AB$3:$AB$502,2),""),Opportunities!$AB$3:$AB$502,0))),"")) | F7: =IF(COUNT(Opportunities!$AB$3:$AB$502)<2,"",IFERROR(IF(INDEX(Opportunities!$J$3:$J$502,MATCH(IFERROR(SMALL(Opportunities!$AB$3:$AB$502,2),""),Opportunities!$AB$3:$AB$502,0))="","",INDEX(Opportunities!$J$3:$J$502,MATCH(IFERROR(SMALL(Opportunities!$AB$3:$AB$502,2),""),Opportunities!$AB$3:$AB$502,0))),"")) | G7: =IF(COUNT(Opportunities!$AB$3:$AB$502)<2,"",IFERROR(IF(INDEX(Opportunities!$K$3:$K$502,MATCH(IFERROR(SMALL(Opportunities!$AB$3:$AB$502,2),""),Opportunities!$AB$3:$AB$502,0))="","",INDEX(Opportunities!$K$3:$K$502,MATCH(IFERROR(SMALL(Opportunities!$AB$3:$AB$502,2),""),Opportunities!$AB$3:$AB$502,0))),"")) | H7: =IF(COUNT(Opportunities!$AB$3:$AB$502)<2,"",IFERROR(IF(INDEX(Opportunities!$P$3:$P$502,MATCH(IFERROR(SMALL(Opportunities!$AB$3:$AB$502,2),""),Opportunities!$AB$3:$AB$502,0))="","",INDEX(Opportunities!$P$3:$P$502,MATCH(IFERROR(SMALL(Opportunities!$AB$3:$AB$502,2),""),Opportunities!$AB$3:$AB$502,0))),"")) | I7: =IF(COUNT(Opportunities!$AB$3:$AB$502)<2,"",IFERROR(IF(INDEX(Opportunities!$Q$3:$Q$502,MATCH(IFERROR(SMALL(Opportunities!$AB$3:$AB$502,2),""),Opportunities!$AB$3:$AB$502,0))="","",INDEX(Opportunities!$Q$3:$Q$502,MATCH(IFERROR(SMALL(Opportunities!$AB$3:$AB$502,2),""),Opportunities!$AB$3:$AB$502,0))),""))
A8: Low Priority | B8: =COUNTIF(Companies!$AE$3:$AE$502,"Low Priority") -> 1 | D8: =IF(COUNT(Opportunities!$AB$3:$AB$502)<3,"",IFERROR(IF(INDEX(Opportunities!$A$3:$A$502,MATCH(IFERROR(SMALL(Opportunities!$AB$3:$AB$502,3),""),Opportunities!$AB$3:$AB$502,0))="","",INDEX(Opportunities!$A$3:$A$502,MATCH(IFERROR(SMALL(Opportunities!$AB$3:$AB$502,3),""),Opportunities!$AB$3:$AB$502,0))),"")) | E8: =IF(COUNT(Opportunities!$AB$3:$AB$502)<3,"",IFERROR(IF(INDEX(Opportunities!$B$3:$B$502,MATCH(IFERROR(SMALL(Opportunities!$AB$3:$AB$502,3),""),Opportunities!$AB$3:$AB$502,0))="","",INDEX(Opportunities!$B$3:$B$502,MATCH(IFERROR(SMALL(Opportunities!$AB$3:$AB$502,3),""),Opportunities!$AB$3:$AB$502,0))),"")) | F8: =IF(COUNT(Opportunities!$AB$3:$AB$502)<3,"",IFERROR(IF(INDEX(Opportunities!$J$3:$J$502,MATCH(IFERROR(SMALL(Opportunities!$AB$3:$AB$502,3),""),Opportunities!$AB$3:$AB$502,0))="","",INDEX(Opportunities!$J$3:$J$502,MATCH(IFERROR(SMALL(Opportunities!$AB$3:$AB$502,3),""),Opportunities!$AB$3:$AB$502,0))),"")) | G8: =IF(COUNT(Opportunities!$AB$3:$AB$502)<3,"",IFERROR(IF(INDEX(Opportunities!$K$3:$K$502,MATCH(IFERROR(SMALL(Opportunities!$AB$3:$AB$502,3),""),Opportunities!$AB$3:$AB$502,0))="","",INDEX(Opportunities!$K$3:$K$502,MATCH(IFERROR(SMALL(Opportunities!$AB$3:$AB$502,3),""),Opportunities!$AB$3:$AB$502,0))),"")) | H8: =IF(COUNT(Opportunities!$AB$3:$AB$502)<3,"",IFERROR(IF(INDEX(Opportunities!$P$3:$P$502,MATCH(IFERROR(SMALL(Opportunities!$AB$3:$AB$502,3),""),Opportunities!$AB$3:$AB$502,0))="","",INDEX(Opportunities!$P$3:$P$502,MATCH(IFERROR(SMALL(Opportunities!$AB$3:$AB$502,3),""),Opportunities!$AB$3:$AB$502,0))),"")) | I8: =IF(COUNT(Opportunities!$AB$3:$AB$502)<3,"",IFERROR(IF(INDEX(Opportunities!$Q$3:$Q$502,MATCH(IFERROR(SMALL(Opportunities!$AB$3:$AB$502,3),""),Opportunities!$AB$3:$AB$502,0))="","",INDEX(Opportunities!$Q$3:$Q$502,MATCH(IFERROR(SMALL(Opportunities!$AB$3:$AB$502,3),""),Opportunities!$AB$3:$AB$502,0))),""))
A9: Research | B9: =COUNTIF(Companies!$AE$3:$AE$502,"Research") -> 2 | D9: =IF(COUNT(Opportunities!$AB$3:$AB$502)<4,"",IFERROR(IF(INDEX(Opportunities!$A$3:$A$502,MATCH(IFERROR(SMALL(Opportunities!$AB$3:$AB$502,4),""),Opportunities!$AB$3:$AB$502,0))="","",INDEX(Opportunities!$A$3:$A$502,MATCH(IFERROR(SMALL(Opportunities!$AB$3:$AB$502,4),""),Opportunities!$AB$3:$AB$502,0))),"")) | E9: =IF(COUNT(Opportunities!$AB$3:$AB$502)<4,"",IFERROR(IF(INDEX(Opportunities!$B$3:$B$502,MATCH(IFERROR(SMALL(Opportunities!$AB$3:$AB$502,4),""),Opportunities!$AB$3:$AB$502,0))="","",INDEX(Opportunities!$B$3:$B$502,MATCH(IFERROR(SMALL(Opportunities!$AB$3:$AB$502,4),""),Opportunities!$AB$3:$AB$502,0))),"")) | F9: =IF(COUNT(Opportunities!$AB$3:$AB$502)<4,"",IFERROR(IF(INDEX(Opportunities!$J$3:$J$502,MATCH(IFERROR(SMALL(Opportunities!$AB$3:$AB$502,4),""),Opportunities!$AB$3:$AB$502,0))="","",INDEX(Opportunities!$J$3:$J$502,MATCH(IFERROR(SMALL(Opportunities!$AB$3:$AB$502,4),""),Opportunities!$AB$3:$AB$502,0))),"")) | G9: =IF(COUNT(Opportunities!$AB$3:$AB$502)<4,"",IFERROR(IF(INDEX(Opportunities!$K$3:$K$502,MATCH(IFERROR(SMALL(Opportunities!$AB$3:$AB$502,4),""),Opportunities!$AB$3:$AB$502,0))="","",INDEX(Opportunities!$K$3:$K$502,MATCH(IFERROR(SMALL(Opportunities!$AB$3:$AB$502,4),""),Opportunities!$AB$3:$AB$502,0))),"")) | H9: =IF(COUNT(Opportunities!$AB$3:$AB$502)<4,"",IFERROR(IF(INDEX(Opportunities!$P$3:$P$502,MATCH(IFERROR(SMALL(Opportunities!$AB$3:$AB$502,4),""),Opportunities!$AB$3:$AB$502,0))="","",INDEX(Opportunities!$P$3:$P$502,MATCH(IFERROR(SMALL(Opportunities!$AB$3:$AB$502,4),""),Opportunities!$AB$3:$AB$502,0))),"")) | I9: =IF(COUNT(Opportunities!$AB$3:$AB$502)<4,"",IFERROR(IF(INDEX(Opportunities!$Q$3:$Q$502,MATCH(IFERROR(SMALL(Opportunities!$AB$3:$AB$502,4),""),Opportunities!$AB$3:$AB$502,0))="","",INDEX(Opportunities!$Q$3:$Q$502,MATCH(IFERROR(SMALL(Opportunities!$AB$3:$AB$502,4),""),Opportunities!$AB$3:$AB$502,0))),""))
A10: Paths in progress (max) | B10: =COUNTIF(Companies!$V$3:$V$502,"Yes")&" / "&S_PathCap -> 1 / 5 | D10: =IF(COUNT(Opportunities!$AB$3:$AB$502)<5,"",IFERROR(IF(INDEX(Opportunities!$A$3:$A$502,MATCH(IFERROR(SMALL(Opportunities!$AB$3:$AB$502,5),""),Opportunities!$AB$3:$AB$502,0))="","",INDEX(Opportunities!$A$3:$A$502,MATCH(IFERROR(SMALL(Opportunities!$AB$3:$AB$502,5),""),Opportunities!$AB$3:$AB$502,0))),"")) | E10: =IF(COUNT(Opportunities!$AB$3:$AB$502)<5,"",IFERROR(IF(INDEX(Opportunities!$B$3:$B$502,MATCH(IFERROR(SMALL(Opportunities!$AB$3:$AB$502,5),""),Opportunities!$AB$3:$AB$502,0))="","",INDEX(Opportunities!$B$3:$B$502,MATCH(IFERROR(SMALL(Opportunities!$AB$3:$AB$502,5),""),Opportunities!$AB$3:$AB$502,0))),"")) | F10: =IF(COUNT(Opportunities!$AB$3:$AB$502)<5,"",IFERROR(IF(INDEX(Opportunities!$J$3:$J$502,MATCH(IFERROR(SMALL(Opportunities!$AB$3:$AB$502,5),""),Opportunities!$AB$3:$AB$502,0))="","",INDEX(Opportunities!$J$3:$J$502,MATCH(IFERROR(SMALL(Opportunities!$AB$3:$AB$502,5),""),Opportunities!$AB$3:$AB$502,0))),"")) | G10: =IF(COUNT(Opportunities!$AB$3:$AB$502)<5,"",IFERROR(IF(INDEX(Opportunities!$K$3:$K$502,MATCH(IFERROR(SMALL(Opportunities!$AB$3:$AB$502,5),""),Opportunities!$AB$3:$AB$502,0))="","",INDEX(Opportunities!$K$3:$K$502,MATCH(IFERROR(SMALL(Opportunities!$AB$3:$AB$502,5),""),Opportunities!$AB$3:$AB$502,0))),"")) | H10: =IF(COUNT(Opportunities!$AB$3:$AB$502)<5,"",IFERROR(IF(INDEX(Opportunities!$P$3:$P$502,MATCH(IFERROR(SMALL(Opportunities!$AB$3:$AB$502,5),""),Opportunities!$AB$3:$AB$502,0))="","",INDEX(Opportunities!$P$3:$P$502,MATCH(IFERROR(SMALL(Opportunities!$AB$3:$AB$502,5),""),Opportunities!$AB$3:$AB$502,0))),"")) | I10: =IF(COUNT(Opportunities!$AB$3:$AB$502)<5,"",IFERROR(IF(INDEX(Opportunities!$Q$3:$Q$502,MATCH(IFERROR(SMALL(Opportunities!$AB$3:$AB$502,5),""),Opportunities!$AB$3:$AB$502,0))="","",INDEX(Opportunities!$Q$3:$Q$502,MATCH(IFERROR(SMALL(Opportunities!$AB$3:$AB$502,5),""),Opportunities!$AB$3:$AB$502,0))),""))
D11: =IF(COUNT(Opportunities!$AB$3:$AB$502)<6,"",IFERROR(IF(INDEX(Opportunities!$A$3:$A$502,MATCH(IFERROR(SMALL(Opportunities!$AB$3:$AB$502,6),""),Opportunities!$AB$3:$AB$502,0))="","",INDEX(Opportunities!$A$3:$A$502,MATCH(IFERROR(SMALL(Opportunities!$AB$3:$AB$502,6),""),Opportunities!$AB$3:$AB$502,0))),"")) | E11: =IF(COUNT(Opportunities!$AB$3:$AB$502)<6,"",IFERROR(IF(INDEX(Opportunities!$B$3:$B$502,MATCH(IFERROR(SMALL(Opportunities!$AB$3:$AB$502,6),""),Opportunities!$AB$3:$AB$502,0))="","",INDEX(Opportunities!$B$3:$B$502,MATCH(IFERROR(SMALL(Opportunities!$AB$3:$AB$502,6),""),Opportunities!$AB$3:$AB$502,0))),"")) | F11: =IF(COUNT(Opportunities!$AB$3:$AB$502)<6,"",IFERROR(IF(INDEX(Opportunities!$J$3:$J$502,MATCH(IFERROR(SMALL(Opportunities!$AB$3:$AB$502,6),""),Opportunities!$AB$3:$AB$502,0))="","",INDEX(Opportunities!$J$3:$J$502,MATCH(IFERROR(SMALL(Opportunities!$AB$3:$AB$502,6),""),Opportunities!$AB$3:$AB$502,0))),"")) | G11: =IF(COUNT(Opportunities!$AB$3:$AB$502)<6,"",IFERROR(IF(INDEX(Opportunities!$K$3:$K$502,MATCH(IFERROR(SMALL(Opportunities!$AB$3:$AB$502,6),""),Opportunities!$AB$3:$AB$502,0))="","",INDEX(Opportunities!$K$3:$K$502,MATCH(IFERROR(SMALL(Opportunities!$AB$3:$AB$502,6),""),Opportunities!$AB$3:$AB$502,0))),"")) | H11: =IF(COUNT(Opportunities!$AB$3:$AB$502)<6,"",IFERROR(IF(INDEX(Opportunities!$P$3:$P$502,MATCH(IFERROR(SMALL(Opportunities!$AB$3:$AB$502,6),""),Opportunities!$AB$3:$AB$502,0))="","",INDEX(Opportunities!$P$3:$P$502,MATCH(IFERROR(SMALL(Opportunities!$AB$3:$AB$502,6),""),Opportunities!$AB$3:$AB$502,0))),"")) | I11: =IF(COUNT(Opportunities!$AB$3:$AB$502)<6,"",IFERROR(IF(INDEX(Opportunities!$Q$3:$Q$502,MATCH(IFERROR(SMALL(Opportunities!$AB$3:$AB$502,6),""),Opportunities!$AB$3:$AB$502,0))="","",INDEX(Opportunities!$Q$3:$Q$502,MATCH(IFERROR(SMALL(Opportunities!$AB$3:$AB$502,6),""),Opportunities!$AB$3:$AB$502,0))),""))
A12: Semester money (recorded amounts only, no estimates) | D12: =IF(COUNT(Opportunities!$AB$3:$AB$502)<7,"",IFERROR(IF(INDEX(Opportunities!$A$3:$A$502,MATCH(IFERROR(SMALL(Opportunities!$AB$3:$AB$502,7),""),Opportunities!$AB$3:$AB$502,0))="","",INDEX(Opportunities!$A$3:$A$502,MATCH(IFERROR(SMALL(Opportunities!$AB$3:$AB$502,7),""),Opportunities!$AB$3:$AB$502,0))),"")) | E12: =IF(COUNT(Opportunities!$AB$3:$AB$502)<7,"",IFERROR(IF(INDEX(Opportunities!$B$3:$B$502,MATCH(IFERROR(SMALL(Opportunities!$AB$3:$AB$502,7),""),Opportunities!$AB$3:$AB$502,0))="","",INDEX(Opportunities!$B$3:$B$502,MATCH(IFERROR(SMALL(Opportunities!$AB$3:$AB$502,7),""),Opportunities!$AB$3:$AB$502,0))),"")) | F12: =IF(COUNT(Opportunities!$AB$3:$AB$502)<7,"",IFERROR(IF(INDEX(Opportunities!$J$3:$J$502,MATCH(IFERROR(SMALL(Opportunities!$AB$3:$AB$502,7),""),Opportunities!$AB$3:$AB$502,0))="","",INDEX(Opportunities!$J$3:$J$502,MATCH(IFERROR(SMALL(Opportunities!$AB$3:$AB$502,7),""),Opportunities!$AB$3:$AB$502,0))),"")) | G12: =IF(COUNT(Opportunities!$AB$3:$AB$502)<7,"",IFERROR(IF(INDEX(Opportunities!$K$3:$K$502,MATCH(IFERROR(SMALL(Opportunities!$AB$3:$AB$502,7),""),Opportunities!$AB$3:$AB$502,0))="","",INDEX(Opportunities!$K$3:$K$502,MATCH(IFERROR(SMALL(Opportunities!$AB$3:$AB$502,7),""),Opportunities!$AB$3:$AB$502,0))),"")) | H12: =IF(COUNT(Opportunities!$AB$3:$AB$502)<7,"",IFERROR(IF(INDEX(Opportunities!$P$3:$P$502,MATCH(IFERROR(SMALL(Opportunities!$AB$3:$AB$502,7),""),Opportunities!$AB$3:$AB$502,0))="","",INDEX(Opportunities!$P$3:$P$502,MATCH(IFERROR(SMALL(Opportunities!$AB$3:$AB$502,7),""),Opportunities!$AB$3:$AB$502,0))),"")) | I12: =IF(COUNT(Opportunities!$AB$3:$AB$502)<7,"",IFERROR(IF(INDEX(Opportunities!$Q$3:$Q$502,MATCH(IFERROR(SMALL(Opportunities!$AB$3:$AB$502,7),""),Opportunities!$AB$3:$AB$502,0))="","",INDEX(Opportunities!$Q$3:$Q$502,MATCH(IFERROR(SMALL(Opportunities!$AB$3:$AB$502,7),""),Opportunities!$AB$3:$AB$502,0))),""))
